#VRML_SIM R2025a utf8

EXTERNPROTO "https://raw.githubusercontent.com/cyberbotics/webots/R2025a/projects/objects/backgrounds/protos/TexturedBackground.proto"
EXTERNPROTO "https://raw.githubusercontent.com/cyberbotics/webots/R2025a/projects/objects/backgrounds/protos/TexturedBackgroundLight.proto"
EXTERNPROTO "https://raw.githubusercontent.com/cyberbotics/webots/R2025a/projects/objects/floors/protos/RectangleArena.proto"
EXTERNPROTO "https://raw.githubusercontent.com/cyberbotics/webots/R2025a/projects/objects/balls/protos/RobocupSoccerBall.proto"
EXTERNPROTO "https://raw.githubusercontent.com/cyberbotics/webots/R2025a/projects/objects/plants/protos/FlowerPot.proto"

WorldInfo {
}
Viewpoint {
  orientation 0.14684017600464755 0.08406268258093948 -0.9855817713960726 2.114178226654036
  position 0.23046889571300677 1.2124540886879447 0.34253522259243624
}
TexturedBackground {
}
TexturedBackgroundLight {
}
RectangleArena {
  translation -0.33 0.35 0
}
Robot {
  translation -0.15099580886486955 0.23539941539716294 0.0497227681669745
  rotation -1.6323056984724718e-05 -8.752427691934003e-06 -0.9999999998284763 3.038263310420168
  children [
    DistanceSensor {
      translation -0.03 -0.1 0
      rotation 0 0 1 -1.87
      children [
        DEF sensor Shape {
          appearance PBRAppearance {
            baseColor 0 0 1
            metalness 0
          }
          geometry Box {
            size 0.01 0.01 0.01
          }
        }
      ]
      name "ds_right"
      boundingObject USE sensor
      physics Physics {
      }
    }
    DistanceSensor {
      translation 0.03 -0.1 0
      rotation 0 0 1 -1.27
      children [
        DEF sensor Shape {
          appearance PBRAppearance {
            baseColor 0 0 1
            metalness 0
          }
          geometry Box {
            size 0.01 0.01 0.01
          }
        }
      ]
      name "ds_left"
      boundingObject USE sensor
      physics Physics {
      }
    }
    HingeJoint {
      jointParameters HingeJointParameters {
        position 15540.097645063039
        anchor -0.06 -0.05 -0.01
      }
      device [
        RotationalMotor {
          name "wheel1"
        }
      ]
      endPoint Solid {
        translation -0.06000000236423284 -0.05000381929642386 -0.010000808373841858
        rotation -0.6139566980977929 -0.4967031610240287 -0.6134681268734289 4.064240469872989
        children [
          DEF wheel Shape {
            appearance PBRAppearance {
              baseColor 0 0 0
              metalness 0
            }
            geometry Cylinder {
              height 0.02
              radius 0.04
            }
          }
        ]
        name "solid(3)"
        boundingObject USE wheel
        physics Physics {
        }
        linearVelocity -0.004126138994345527 0.0397870343926548 -3.967872715984838e-07
        angularVelocity -0.9946624524236207 -0.10318490100040642 1.1785558028794732e-05
      }
    }
    HingeJoint {
      jointParameters HingeJointParameters {
        position 6644.912391947859
        anchor 0.06 0.05 -0.01
      }
      device [
        RotationalMotor {
          name "wheel2"
        }
      ]
      endPoint Solid {
        translation 0.06000000220838095 0.05000169941128613 -0.010003565123635922
        rotation -0.6985563879932613 0.15752695400442185 -0.6980001658709667 2.828861637529377
        children [
          DEF wheel Shape {
            appearance PBRAppearance {
              baseColor 0 0 0
              metalness 0
            }
            geometry Cylinder {
              height 0.02
              radius 0.04
            }
          }
        ]
        name "solid(2)"
        boundingObject USE wheel
        physics Physics {
        }
        linearVelocity -0.004128650769696776 0.03978595288102038 4.0076856327327886e-07
        angularVelocity -0.9946623920088691 -0.1031848600702541 1.17776160993092e-05
      }
    }
    HingeJoint {
      jointParameters HingeJointParameters {
        position 15540.097687540434
        anchor -0.06 0.05 -0.01
      }
      device [
        RotationalMotor {
          name "wheel3"
        }
      ]
      endPoint Solid {
        translation -0.06000000236423272 0.04999618237430449 -0.010000816227597763
        rotation -0.6139632068219293 -0.49668708295893527 -0.6134746305192064 4.064214664796126
        children [
          DEF wheel Shape {
            appearance PBRAppearance {
              baseColor 0 0 0
              metalness 0
            }
            geometry Cylinder {
              height 0.02
              radius 0.04
            }
          }
        ]
        name "solid(1)"
        boundingObject USE wheel
        physics Physics {
        }
        linearVelocity -0.004128734064453112 0.03978675804307384 -3.730541704396313e-07
        angularVelocity -0.994662452800612 -0.10318489181526186 1.1749358641108773e-05
      }
    }
    HingeJoint {
      jointParameters HingeJointParameters {
        position 6644.9138962769375
        anchor 0.06 -0.05 -0.01
      }
      device [
        RotationalMotor {
          name "wheel4"
        }
      ]
      endPoint Solid {
        translation 0.06000000220838101 -0.04999830154205226 -0.010003565577912042
        rotation -0.6984955447155885 0.15806520297836418 -0.6979393710200638 2.8278104966566726
        children [
          DEF wheel Shape {
            appearance PBRAppearance {
              baseColor 0 0 0
              metalness 0
            }
            geometry Cylinder {
              height 0.02
              radius 0.04
            }
          }
        ]
        boundingObject USE wheel
        physics Physics {
        }
        linearVelocity -0.00412605493106761 0.03978622179105097 3.7760736286710844e-07
        angularVelocity -0.9946623910382193 -0.10318486919906047 1.1813852265217137e-05
      }
    }
    DEF body Shape {
      appearance PBRAppearance {
        baseColor 0.505882 0.239216 0.611765
        metalness 0
      }
      geometry Box {
        size 0.1 0.2 0.05
      }
    }
  ]
  boundingObject USE body
  physics Physics {
  }
  controller "my_controller3"
  linearVelocity -0.0041280042338628165 0.03978861889167376 1.1001017641701235e-06
  angularVelocity 3.8104659595748987e-06 -3.894250717490422e-05 -2.2332927148214467e-05
}
RobocupSoccerBall {
  hidden linearVelocity_0 -5.040220929412395e-151 5.198907115771947e-153 -1.379493193321662e-16
  hidden angularVelocity_0 -7.437635358758145e-152 -7.210616494152205e-150 4.886501590528978e-166
  translation -0.44267383820501116 0.5515827223606584 0.06967823200000008
  rotation -0.5534620543325554 -0.6223821244442724 -0.5534620543327445 2.028163488003031
}
FlowerPot {
  translation 0 0.1 0
}
